---
layout: doc
title: traceback 模块 - 异常追踪与调试
permalink: /docs/stdlib/traceback/  
category: stdlib
tags: [异常处理, 调试, traceback, 错误追踪, 堆栈信息]
description: Python traceback 模块详解 - 提取、格式化和打印 Python 程序的堆栈追踪信息
author: Python教程
date: 2024-12-19
updated: 2024-12-19
version: 1.0
difficulty: "中级"
---

# traceback 模块 - 异常追踪与调试

## 📝 概述

traceback 模块是 Python 标准库中用于提取、格式化和打印 Python 程序的堆栈追踪（stack traces）信息的重要工具。当我们需要详细的异常信息来调试程序时，简单的异常处理往往无法提供足够的信息，而 traceback 模块可以帮助我们获得更加详细和有用的调试信息。

刚接触 Python 的时候，简单的异常处理已经可以帮助我们解决大多数问题，但是随着逐渐地深入，我们会发现有很多情况下简单的异常处理已经无法解决问题了。单纯的打印异常所能提供的信息会非常有限，这种情况下我们很难定位在哪块代码出的问题，以及如何出现这种异常。

## 🎯 学习目标

- 理解 traceback object 的概念和作用
- 掌握 sys.exc_info() 函数的使用方法
- 学会使用 traceback 模块的各种函数
- 能够在多线程环境中获取异常信息
- 掌握异常信息的格式化和输出技巧

## 📋 前置知识

- Python 基础语法和异常处理机制
- 了解 Python 的模块导入和使用
- 熟悉基本的调试概念
- 多线程编程基础（用于高级用法）

## 🔍 详细内容

### 基本概念

在学习 traceback 模块之前，我们先来看一个简单异常处理的例子：

```python
def func1():
    raise Exception("--func1 exception--")

def main():
    try:
        func1()
    except Exception as e:
        print(e)  # Python 3 中使用 print(e)

if __name__ == '__main__':
    main()
```

执行后输出如下：

```
--func1 exception--
```

通过示例，我们发现普通的打印异常只有很少量的信息（通常是异常的 value 值），这种情况下我们很难定位在哪块代码出的问题，以及如何出现这种异常。

### sys.exc_info 和 traceback object

Python 程序的 traceback 信息均来源于一个叫做 traceback object 的对象，而这个 traceback object 通常是通过函数 `sys.exc_info()` 来获取的。

```python
import sys

def func1():
    raise NameError("--func1 exception--")

def main():
    try:
        func1()
    except Exception as e:
        exc_type, exc_value, exc_traceback_obj = sys.exc_info()
        print("exc_type: %s" % exc_type)
        print("exc_value: %s" % exc_value)
        print("exc_traceback_obj: %s" % exc_traceback_obj)

if __name__ == '__main__':
    main()
```

执行后输出如下：

```
exc_type: <class 'NameError'>
exc_value: --func1 exception--
exc_traceback_obj: <traceback object at 0x7faddf5d93b0>
```

通过以上示例我们可以看出，`sys.exc_info()` 获取了当前处理的 exception 的相关信息，并返回一个元组：
- 第一个数据是异常的类型（示例是 NameError 类型）
- 第二个返回值是异常的 value 值
- 第三个就是我们要的 traceback object

有了 traceback object 我们就可以通过 traceback module 来打印和格式化 traceback 的相关信息。

### traceback 模块核心函数

Python 的 traceback module 提供一整套接口用于提取、格式化和打印 Python 程序的 stack traces 信息。

#### print_tb 函数

```python
import sys
import traceback

def func1():
    raise NameError("--func1 exception--")

def main():
    try:
        func1()
    except Exception as e:
        exc_type, exc_value, exc_traceback_obj = sys.exc_info()
        traceback.print_tb(exc_traceback_obj)

if __name__ == '__main__':
    main()
```

输出：

```
  File "<ipython-input-23-52bdf2c9489c>", line 11, in main
    func1()
  File "<ipython-input-23-52bdf2c9489c>", line 6, in func1
    raise NameError("--func1 exception--")
```

这里我们可以发现打印的异常信息更加详细了。

**函数语法**：

```python
traceback.print_tb(tb[, limit[, file]])
```

**参数说明**：

| 参数 | 类型 | 必需 | 默认值 | 说明 |
|------|------|------|--------|------|
| tb | traceback object | 是 | 无 | 通过 sys.exc_info 获取到的 traceback 对象 |
| limit | int | 否 | None | 限制 stack trace 层级数，None 表示打印所有层级 |
| file | file-like object | 否 | sys.stderr | 设置打印的输出流 |

#### print_exception 函数

```python
import sys
import traceback

def func1():
    raise NameError("--func1 exception--")

def func2():
    func1()

def main():
    try:
        func2()
    except Exception as e:
        exc_type, exc_value, exc_traceback_obj = sys.exc_info()
        traceback.print_exception(exc_type, exc_value, exc_traceback_obj, limit=2, file=sys.stdout)

if __name__ == '__main__':
    main()
```

输出：

```
Traceback (most recent call last):
  File "<ipython-input-24-a68061acf52f>", line 13, in main
    func2()
  File "<ipython-input-24-a68061acf52f>", line 9, in func2
    func1()
NameError: --func1 exception--
```

**函数语法**：

```python
traceback.print_exception(etype, value, tb[, limit[, file]])
```

**与 print_tb 的区别**：
- 多了两个参数 etype 和 value，分别是 exception type 和 exception value
- 加上 tb（traceback object），正好是 sys.exc_info() 返回的三个值
- 打印信息多了开头的 "Traceback (most...)" 信息以及最后一行的异常类型和 value 信息
- 当异常为 SyntaxError 时，会有 "^" 来指示语法错误的位置

#### print_exc 函数（最常用）

print_exc 是简化版的 print_exception，由于 exception type、value 和 traceback object 都可以通过 sys.exc_info() 获取，因此 print_exc() 就自动执行 exc_info() 来帮助获取这三个参数了，也因此这个函数是我们的程序中最常用的，因为它足够简单。

```python
import sys
import traceback

def func1():
    raise NameError("--func1 exception--")

def func2():
    func1()

def main():
    try:
        func2()
    except Exception as e:
        traceback.print_exc(limit=1, file=sys.stdout)

if __name__ == '__main__':
    main()
```

输出（由于 limit=1，因此只有一个层级被打印出来）：

```
Traceback (most recent call last):
  File "<ipython-input-25-a1f5c73b97c4>", line 13, in main
    func2()
NameError: --func1 exception--
```

**函数语法**：

```python
traceback.print_exc([limit[, file]])
```

**参数说明**：

| 参数 | 类型 | 必需 | 默认值 | 说明 |
|------|------|------|--------|------|
| limit | int | 否 | None | 限制 stack trace 层级数 |
| file | file-like object | 否 | sys.stderr | 设置打印的输出流 |

#### format_exc 函数

```python
import logging
import sys
import traceback

logger = logging.getLogger("traceback_test")

def func1():
    raise NameError("--func1 exception--")

def func2():
    func1()

def main():
    try:
        func2()
    except Exception as e:
        # 注意：format_exc 不需要 file 参数，因为它返回字符串而不是直接打印
        error_msg = traceback.format_exc(limit=1)
        logger.error(error_msg)

if __name__ == '__main__':
    main()
```

从这个例子可以看出有时候我们想得到的是一个字符串，比如我们想通过 logger 将异常记录在日志里，这个时候就需要 format_exc 了，这个也是最常用的一个函数，它跟 print_exc 用法相同，只是不直接打印而是返回了字符串。

## 💡 实际应用

### 基础用法

#### 简单的异常信息获取

```python
import traceback

def divide_numbers(a, b):
    """除法运算示例"""
    return a / b

def main():
    try:
        result = divide_numbers(10, 0)
        print(f"结果: {result}")
    except Exception as e:
        print("发生异常:")
        traceback.print_exc()

if __name__ == '__main__':
    main()
```

#### 异常信息记录到日志

```python
import logging
import traceback

# 配置日志
logging.basicConfig(
    level=logging.ERROR,
    format='%(asctime)s - %(levelname)s - %(message)s',
    filename='error.log'
)

def risky_operation():
    """可能出错的操作"""
    data = [1, 2, 3]
    return data[10]  # 故意触发 IndexError

def main():
    try:
        risky_operation()
    except Exception as e:
        # 将完整的异常信息记录到日志
        error_msg = traceback.format_exc()
        logging.error(f"程序执行出错:\n{error_msg}")

if __name__ == '__main__':
    main()
```

### 高级用法

#### 获取线程中的异常信息

通常情况下我们无法将多线程中的异常带回主线程，所以也就无法打印线程中的异常，而通过上边学到这些知识，我们可以对线程做如下修改，从而实现捕获线程异常的目的。

```python
import threading
import traceback

def my_func():
    """线程中执行的函数，故意抛出异常"""
    raise BaseException("thread exception")

class ExceptionThread(threading.Thread):
    """能够捕获异常的线程类"""

    def __init__(self, group=None, target=None, name=None, args=(), kwargs=None, verbose=None):
        """
        将线程的异常重定向到异常处理器
        """
        threading.Thread.__init__(self, group, target, name, args, kwargs, verbose)
        if kwargs is None:
            kwargs = {}
        self._target = target
        self._args = args
        self._kwargs = kwargs
        self._exc = None

    def run(self):
        """重写 run 方法以捕获异常"""
        try:
            if self._target:
                self._target()
        except BaseException as e:
            import sys
            self._exc = sys.exc_info()
        finally:
            # 避免循环引用，如果线程正在运行一个函数，
            # 该函数的参数有一个成员指向线程
            del self._target, self._args, self._kwargs

    def join(self):
        """重写 join 方法以传播异常"""
        threading.Thread.join(self)
        if self._exc:
            msg = "Thread '%s' threw an exception: %s" % (self.getName(), self._exc[1])
            new_exc = Exception(msg)
            # Python 3 语法调整
            raise new_exc.with_traceback(self._exc[2])

# 使用示例
t = ExceptionThread(target=my_func, name='my_thread')
t.start()
try:
    t.join()
except:
    traceback.print_exc()
```

输出如下：

```
Traceback (most recent call last):
  File "/data/code/testcode/thread_exc.py", line 43, in <module>
    t.join()
  File "/data/code/testcode/thread_exc.py", line 23, in run
    self._target()
  File "/data/code/testcode/thread_exc.py", line 5, in my_func
    raise BaseException("thread exception")
Exception: Thread 'my_thread' threw an exception: thread exception
```

这样我们就得到了线程中的异常信息。

#### 异常信息的格式化处理

```python
import traceback
import sys

def custom_exception_handler(exc_type, exc_value, exc_traceback):
    """自定义异常处理器"""
    if issubclass(exc_type, KeyboardInterrupt):
        # 对于 KeyboardInterrupt，只打印简单信息
        print("程序被用户中断")
        return
    
    # 格式化异常信息
    tb_lines = traceback.format_exception(exc_type, exc_value, exc_traceback)
    tb_text = ''.join(tb_lines)
    
    # 自定义格式输出
    print("=" * 50)
    print("发生了一个异常:")
    print("-" * 50)
    print(tb_text)
    print("=" * 50)

def problematic_function():
    """有问题的函数"""
    x = 1 / 0  # 除零错误

def main():
    # 设置自定义异常处理器
    sys.excepthook = custom_exception_handler
    
    # 触发异常
    problematic_function()

if __name__ == '__main__':
    main()
```

### 实际案例

#### 调试装饰器

```python
import functools
import traceback

def debug_on_error(func):
    """在函数出错时打印详细调试信息的装饰器"""
    @functools.wraps(func)
    def wrapper(*args, **kwargs):
        try:
            return func(*args, **kwargs)
        except Exception as e:
            print(f"函数 {func.__name__} 执行出错:")
            print(f"参数: args={args}, kwargs={kwargs}")
            print("异常详情:")
            traceback.print_exc()
            raise  # 重新抛出异常
    return wrapper

@debug_on_error
def calculate_average(numbers):
    """计算平均值"""
    return sum(numbers) / len(numbers)

# 使用示例
if __name__ == '__main__':
    # 这会触发异常，因为列表为空
    try:
        result = calculate_average([])
    except:
        print("异常已被捕获并处理")
```

#### 异常上下文管理器

```python
import traceback
from contextlib import contextmanager

@contextmanager
def exception_logger(operation_name="操作"):
    """异常日志记录上下文管理器"""
    try:
        print(f"开始执行 {operation_name}")
        yield
        print(f"{operation_name} 执行成功")
    except Exception as e:
        print(f"{operation_name} 执行失败:")
        print(f"异常类型: {type(e).__name__}")
        print(f"异常信息: {e}")
        print("详细追踪:")
        traceback.print_exc()
        raise

# 使用示例
def main():
    with exception_logger("文件读取操作"):
        with open("nonexistent_file.txt", "r") as f:
            content = f.read()

if __name__ == '__main__':
    try:
        main()
    except:
        print("程序执行完毕")
```

## ⚠️ 注意事项

- **Python 版本差异**：示例中的一些代码是基于 Python 2 的语法，在 Python 3 中需要相应调整（如 print 语句变为 print 函数）
- **性能考虑**：频繁使用 traceback 信息可能会影响性能，特别是在生产环境中
- **内存泄漏**：traceback object 会保持对栈帧的引用，可能导致内存泄漏，使用完毕后应及时清理
- **线程安全**：在多线程环境中使用时需要注意线程安全问题
- **异常传播**：在自定义异常处理时，要注意是否需要重新抛出异常
- **日志级别**：在生产环境中，应该合理设置日志级别，避免敏感信息泄露

## 🔗 相关内容

- [sys 模块 - 系统特定参数和函数](../sys/)
- [logging 模块 - 日志记录和管理](../logging/)
- [threading 模块 - 多线程编程](https://docs.python.org/3/library/threading.html)
- [异常处理基础](../../basics/raise-assert/)

## 📚 扩展阅读

- [Python traceback 官方文档](https://docs.python.org/3/library/traceback.html)
- [Python 异常处理最佳实践](https://docs.python.org/3/tutorial/errors.html)
- [调试技巧与工具](https://docs.python.org/3/library/pdb.html)
- [多线程异常处理模式](https://docs.python.org/3/library/concurrent.futures.html)

## 🏷️ 标签

`异常处理` `调试` `traceback` `错误追踪` `堆栈信息` `多线程异常`

---

**最后更新**: 2024-12-19  
**作者**: Python教程  
**版本**: 1.0